Workbook
Name ForecastHorizon: '[1]Controls and README'!$C$8
Name ForecastRound: '[1]Controls and README'!$C$4
Name ForecastVersion: '[1]Controls and README'!$C$5
Name mpc_fcst_end: [1]VAR_controls!#REF!
Name mpc_fcst_start: [1]VAR_controls!#REF!
Name StartDate: '[1]Controls and README'!$C$3
Name STIFHorizon: '[1]Controls and README'!$C$7

Sheet FAME Persistence2
A1: 122 | B1: Estimation_data
A2: Data_FAME (2) | B2: $BH$10 | C2: A1:A157 | D2: CONV2QA(stif_pu_wgt.m) | E2: 46078.88 | F2: TRUE | G2: CONV2QA(stif_pu_wgt.m) | H2: 1990 | I2: 2028 | J2: 0 | K2: Quarterly | L2: FALSE | M2: TRUE | N2: FALSE
A3: Data_FAME (2) | B3: $BG$10 | C3: A1:A157 | D3: CONV2QA(STIF_GDS_XEATFNAB_wgt.m) | E3: 46078.88 | F3: TRUE | G3: CONV2QA(STIF_GDS_XEATFNAB_wgt.m) | H3: 1990 | I3: 2028 | J3: 0 | K3: Quarterly | L3: FALSE | M3: TRUE | N3: FALSE
A4: Data_FAME (2) | B4: $BF$10 | D4: Refresh | E4: 0
A5: Data_FAME (2) | B5: $D$10 | C5: A1:A157 | D5: N25_cpisa_FIN.q | E5: 46078.81 | F5: TRUE | G5: N25_cpisa_FIN.q | H5: 1990 | I5: 2028 | J5: 0 | K5: Quarterly | L5: FALSE | M5: TRUE | N5: FALSE
A6: Data_FAME (2) | B6: $A$10 | C6: A1:A157 | D6: FAMEDATE | E6: 46078.814 | F6: TRUE | G6: FAMEDATE | H6: 1990 | I6: 2028 | J6: 0 | K6: Quarterly | L6: FALSE | M6: TRUE | N6: FALSE
A7: Data_FAME (2) | B7: $B$10 | C7: A1:A161 | D7: conv2qa(X12(stifidx.m,MULT,1990m2,2025m12)) | E7: 46078.816 | F7: TRUE | G7: conv2qa(X12(stifidx.m,MULT,1990m2,2025m12)) | H7: 1990 | I7: 2029 | J7: 0 | K7: Quarterly | L7: FALSE | M7: TRUE | N7: FALSE
A8: Data_FAME (2) | B8: $C$10 | C8: A1:A157 | D8: conv2qa(X12(fprojm(stifidx_clothingadjusted.m,stifidx.m,"L"),MULT,1990m2,2025m12)) | E8: 46078.817 | F8: TRUE | G8: conv2qa(X12(fprojm(stifidx_clothingadjusted.m,stifidx.m,"L"),MULT,1990m2,2025m12)) | H8: 1990 | I8: 2028 | J8: 0 | K8: Quarterly | L8: FALSE | M8: TRUE | N8: FALSE
A9: Data_FAME (2) | B9: $H$10 | C9: A1:A157 | D9: conv2qa(X12(stif_gds_xeatfnab.m,MULT,1990m2,2025m12)) | E9: 46078.818 | F9: TRUE | G9: conv2qa(X12(stif_gds_xeatfnab.m,MULT,1990m2,2025m12)) | H9: 1990 | I9: 2028 | J9: 0 | K9: Quarterly | L9: FALSE | M9: TRUE | N9: FALSE
A10: Data_FAME (2) | B10: $J$10 | C10: A1:A157 | D10: conv2qa(X12(stif_fnab.m,MULT,1990m2,2025m12)) | E10: 46078.818 | F10: TRUE | G10: conv2qa(X12(stif_fnab.m,MULT,1990m2,2025m12)) | H10: 1990 | I10: 2028 | J10: 0 | K10: Quarterly | L10: FALSE | M10: TRUE | N10: FALSE
A11: Data_FAME (2) | B11: $O$10 | D11: Refresh | E11: 0 | F11: FALSE
A12: Data_FAME (2) | B12: $R$10 | C12: A1:A157 | D12: mod_gdpkp.q | E12: 0 | F12: TRUE | G12: mod_gdpkp.q | H12: 1990 | I12: 2028 | J12: 0 | K12: Quarterly | L12: FALSE | M12: TRUE | N12: FALSE
A13: Data_FAME (2) | B13: $S$10 | D13: Refresh | E13: 0 | F13: FALSE
A14: Data_FAME (2) | B14: $U$10 | C14: A1:A157 | D14: mod_capu.q | E14: 46078.819 | F14: TRUE | G14: mod_capu.q | H14: 1990 | I14: 2028 | J14: 0 | K14: Quarterly | L14: FALSE | M14: TRUE | N14: FALSE
A15: Data_FAME (2) | B15: $V$10 | D15: Refresh | E15: 0 | F15: FALSE
A16: Data_FAME (2) | B16: $X$10 | C16: A1:A157 | D16: mod_hrs.q | E16: 46078.819 | F16: TRUE | G16: mod_hrs.q | H16: 1990 | I16: 2028 | J16: 0 | K16: Quarterly | L16: FALSE | M16: TRUE | N16: FALSE
A17: Data_FAME (2) | B17: $Y$10 | D17: Refresh | E17: 0 | F17: FALSE
A18: Data_FAME (2) | B18: $AA$10 | C18: A1:A157 | D18: mod_unemp.q | E18: 46078.819 | F18: TRUE | G18: mod_unemp.q | H18: 1990 | I18: 2028 | J18: 0 | K18: Quarterly | L18: FALSE | M18: TRUE | N18: FALSE
A19: Data_FAME (2) | B19: $AB$10 | D19: Refresh | E19: 0 | F19: FALSE
A20: Data_FAME (2) | B20: $AD$10 | D20: #N/A | E20: 0 | F20: TRUE | H20: 1990 | I20: 2028 | J20: 0 | K20: Quarterly | L20: FALSE | M20: TRUE | N20: FALSE
A21: Data_FAME (2) | B21: $AE$10 | C21: A1:A157 | D21: conv2qa(OVERLAY(KAJ2_DP.M,KAJ2_HIST.M)) | E21: 0 | F21: TRUE | G21: conv2qa(OVERLAY(KAJ2_DP.M,KAJ2_HIST.M)) | H21: 1990 | I21: 2028 | J21: 0 | K21: Quarterly | L21: FALSE | M21: TRUE | N21: FALSE
A22: Data_FAME (2) | B22: $AF$10 | D22: Refresh | E22: 0 | F22: FALSE
A23: Data_FAME (2) | B23: $AH$10 | D23: #N/A | E23: 0 | F23: TRUE | H23: 1990 | I23: 2028 | J23: 0 | K23: Quarterly | L23: FALSE | M23: TRUE | N23: FALSE
A24: Data_FAME (2) | B24: $AI$10 | C24: A1:A157 | D24: CONV2QA(SERI.B) | E24: 0 | F24: TRUE | G24: CONV2QA(SERI.B) | H24: 1990 | I24: 2028 | J24: 0 | K24: Quarterly | L24: FALSE | M24: TRUE | N24: FALSE
A25: Data_FAME (2) | B25: $AJ$10 | D25: Refresh | E25: 0 | F25: FALSE
A26: Data_FAME (2) | B26: $AL$10 | D26: #N/A | E26: 0 | F26: TRUE | H26: 1990 | I26: 2028 | J26: 0 | K26: Quarterly | L26: FALSE | M26: TRUE | N26: FALSE
A27: Data_FAME (2) | B27: $AM$10 | D27: Refresh | E27: 0 | F27: FALSE
A28: Data_FAME (2) | B28: $AO$10 | C28: A1:A157 | D28: mod_rgawqe.q | E28: 46078.819 | F28: TRUE | G28: mod_rgawqe.q | H28: 1990 | I28: 2028 | J28: 0 | K28: Quarterly | L28: FALSE | M28: TRUE | N28: FALSE
A29: Data_FAME (2) | B29: $AP$10 | D29: Refresh | E29: 0 | F29: FALSE
A30: Data_FAME (2) | B30: $AR$10 | D30: #N/A | E30: 0 | F30: TRUE | H30: 1990 | I30: 2028 | J30: 0 | K30: Quarterly | L30: FALSE | M30: TRUE | N30: FALSE
A31: Data_FAME (2) | B31: $AS$10 | C31: A1:A157 | D31: mod_pmdef.q | E31: 0 | F31: TRUE | G31: mod_pmdef.q | H31: 1990 | I31: 2028 | J31: 0 | K31: Quarterly | L31: FALSE | M31: TRUE | N31: FALSE
A32: Data_FAME (2) | B32: $AT$10 | C32: A1:A157 | D32: N25_pmdef_FIN.q | E32: 0 | F32: TRUE | G32: N25_pmdef_FIN.q | H32: 1990 | I32: 2028 | J32: 0 | K32: Quarterly | L32: FALSE | M32: TRUE | N32: FALSE
A33: Data_FAME (2) | B33: $AU$10 | D33: Refresh | E33: 0 | F33: FALSE
A34: Data_FAME (2) | B34: $AW$10 | C34: A1:A157 | D34: mod_cpif.q | E34: 46078.819 | F34: TRUE | G34: mod_cpif.q | H34: 1990 | I34: 2028 | J34: 0 | K34: Quarterly | L34: FALSE | M34: TRUE | N34: FALSE
A35: Data_FAME (2) | B35: $AX$10 | D35: Refresh | E35: 0 | F35: FALSE
A36: Data_FAME (2) | B36: $AZ$10 | C36: A1:A157 | D36: PUB12MEDIAN.Q | E36: 46078.819 | F36: TRUE | G36: PUB12MEDIAN.Q | H36: 1990 | I36: 2028 | J36: 0 | K36: Quarterly | L36: FALSE | M36: TRUE | N36: FALSE
A37: Data_FAME (2) | B37: $BA$10 | C37: A1:A157 | D37: CONV2QA(cgrp.m) | E37: 0 | F37: TRUE | G37: CONV2QA(cgrp.m) | H37: 1990 | I37: 2028 | J37: 0 | K37: Quarterly | L37: FALSE | M37: TRUE | N37: FALSE
A38: Data_FAME (2) | B38: $BB$10 | C38: A1:A157 | D38: fprojm(PUB12MEDIAN.Q,CONV2QA(cgrp.m),""L"") | E38: 0 | F38: TRUE | G38: fprojm(PUB12MEDIAN.Q,CONV2QA(cgrp.m),""L"") | H38: 1990 | I38: 2028 | J38: 0 | K38: Quarterly | L38: FALSE | M38: TRUE | N38: FALSE
A39: Data_FAME (2) | B39: $BC$10 | D39: Refresh | E39: 0 | F39: FALSE
A40: Data_FAME (2) | B40: $F$10 | C40: A1:A157 | D40: conv2qa(X12(stif_srv.m,MULT,1990m2,2025m12)) | E40: 46078.819 | F40: TRUE | G40: conv2qa(X12(stif_srv.m,MULT,1990m2,2025m12)) | H40: 1990 | I40: 2028 | J40: 0 | K40: Quarterly | L40: FALSE | M40: TRUE | N40: FALSE
...

Sheet datav2
A1: Date | B1: cpi | C1: cpi_a | D1: cpi_f | E1: services | F1: core_gds | G1: food | H1: food_at_nsa | I1: food_at | J1: energy | K1: energy_f | L1: gdpkp | M1: gdpkp_f | N1: capu | O1: capu_f | P1: hrs | Q1: hrs_f | R1: unemp | S1: unemp_f | T1: wage | U1: wage_f | V1: eer | W1: eer_f | X1: ois_rate | Y1: bank_rate | Z1: bank_rate_f | AA1: pmdef | AB1: pmdef_f | AC1: pmdef_xf | AD1: cpif | AE1: cpif_f | AF1: infl_exp | AG1: infl_exp_f | AH1: fat_wgt | AI1: cf_wgt | AJ1: e_wgt | AK1: s_wgt | AL1: infl_target | AM1: ied
A2: 33054 | B2: 55.216192 | C2: 53.449601 | D2: 55.931591 | E2: 37.291624 | F2: 109.4919 | G2: 55.346352 | H2: 46.757461 | I2: 46.254605 | J2: 33.809155 | K2: 33.809155 | L2: 381997 | M2: 381997 | N2: -1.1483808 | O2: 0.93596216 | P2: 906588.84 | Q2: 906588.84 | R2: 0.069184781 | S2: 0.069184781 | T2: 189.32838 | U2: 189.32838 | V2: 93.068646 | W2: 93.068646 | X2: 14.519134 | Y2: 14.875 | Z2: 14.875 | AA2: 0.57773628 | AB2: 0.57773628 | AC2: 0.60985266 | AD2: 67.416856 | AE2: 67.416856 | AF2: 8.6373834 | AG2: 8.6373834 | AH2: 251 | AI2: 359 | AJ2: 96 | AK2: 294 | AL2: 2 | AM2: =+AF2-AL2 -> 6.6373834
A3: 33146 | B3: 56.369272 | C3: 54.565685 | D3: 56.730638 | E3: 38.226404 | F3: 110.77076 | G3: 56.069625 | H3: 46.959972 | I3: 47.031491 | J3: 35.502014 | K3: 35.502014 | L3: 377831 | M3: 377831 | N3: -1.7358221 | O3: -0.79049292 | P3: 901813.5 | Q3: 901813.5 | R3: 0.070779647 | S3: 0.070779647 | T3: 193.61239 | U3: 193.61239 | V3: 99.445968 | W3: 99.445968 | X3: 14.377204 | Y3: 14.875 | Z3: 14.875 | AA3: 0.55930606 | AB3: 0.55930606 | AC3: 0.59130693 | AD3: 68.109698 | AE3: 68.109698 | AF3: 9.1039566 | AG3: 9.1039566 | AH3: 251 | AI3: 359 | AJ3: 96 | AK3: 294 | AL3: 2 | AM3: =+AF3-AL3 -> 7.1039566
A4: 33238 | B4: 57.494732 | C4: 55.655628 | D4: 57.774359 | E4: 39.201503 | F4: 112.05037 | G4: 57.003542 | H4: 47.50451 | I4: 47.936474 | J4: 36.723481 | K4: 36.723481 | L4: 375916 | M4: 375916 | N4: -2.1830843 | O4: -1.1706663 | P4: 892410.87 | Q4: 892410.87 | R4: 0.074650616 | S4: 0.074650616 | T4: 197.31141 | U4: 197.31141 | V4: 99.670858 | W4: 99.670858 | X4: 13.268016 | Y4: 13.9531 | Z4: 13.9531 | AA4: 0.56615029 | AB4: 0.56615029 | AC4: 0.5885035 | AD4: 69.42033 | AE4: 69.42033 | AF4: 7.4794737 | AG4: 7.4794737 | AH4: 251 | AI4: 359 | AJ4: 96 | AK4: 294 | AL4: 2 | AM4: =+AF4-AL4 -> 5.4794737
A5: 33328 | B5: 58.131185 | C5: 56.271618 | D5: 58.016017 | E5: 40.047704 | F5: 112.98292 | G5: 57.575944 | H5: 48.473466 | I5: 48.483131 | J5: 36.121607 | K5: 36.121607 | L5: 374060 | M5: 374060 | N5: -2.9343664 | O5: -1.255856 | P5: 881370.83 | Q5: 881370.83 | R5: 0.079969483 | S5: 0.079969483 | T5: 199.57143 | U5: 199.57143 | V5: 99.118131 | W5: 99.118131 | X5: 12.723411 | Y5: 13.3992 | Z5: 13.3992 | AA5: 0.56293382 | AB5: 0.56293382 | AC5: 0.59734507 | AD5: 70.402484 | AE5: 70.402484 | AF5: 7.1724561 | AG5: 7.1724561 | AH5: 242 | AI5: 363 | AJ5: 93 | AK5: 302 | AL5: 2 | AM5: =+AF5-AL5 -> 5.1724561
A6: 33419 | B6: 59.827705 | C6: 57.9136 | D6: 60.59482 | E6: 41.709306 | F6: 115.1372 | G6: 58.344421 | H6: 50.505217 | I6: 49.975838 | J6: 37.362098 | K6: 37.362098 | L6: 373608 | M6: 373608 | N6: -3.3312328 | O6: -1.273024 | P6: 869788.47 | Q6: 869788.47 | R6: 0.086627038 | S6: 0.086627038 | T6: 204.08804 | U6: 204.08804 | V6: 96.421142 | W6: 96.421142 | X6: 11.097574 | Y6: 11.7379 | Z6: 11.7379 | AA6: 0.57235316 | AB6: 0.57235316 | AC6: 0.60942136 | AD6: 71.079089 | AE6: 71.079089 | AF6: 5.5856456 | AG6: 5.5856456 | AH6: 242 | AI6: 363 | AJ6: 93 | AK6: 302 | AL6: 2 | AM6: =+AF6-AL6 -> 3.5856456
A7: 33511 | B7: 60.749441 | C7: 58.805692 | D7: 61.129417 | E7: 42.478114 | F7: 116.63678 | G7: 58.886712 | H7: 50.449029 | I7: 50.515686 | J7: 38.223615 | K7: 38.223615 | L7: 372878 | M7: 372878 | N7: -3.4757524 | O7: -1.2520863 | P7: 859520.46 | Q7: 859520.46 | R7: 0.09159133 | S7: 0.09159133 | T7: 208.2244 | U7: 208.2244 | V7: 95.722653 | W7: 95.722653 | X7: 10.282062 | Y7: 10.7981 | Z7: 10.7981 | AA7: 0.58356049 | AB7: 0.58356049 | AC7: 0.61934117 | AD7: 71.94639 | AE7: 71.94639 | AF7: 4.6085185 | AG7: 4.6085185 | AH7: 242 | AI7: 363 | AJ7: 93 | AK7: 302 | AL7: 2 | AM7: =+AF7-AL7 -> 2.6085185
A8: 33603 | B8: 61.5371 | C8: 59.568663 | D8: 61.822885 | E8: 43.254296 | F8: 117.83569 | G8: 59.515813 | H8: 50.749747 | I8: 51.223588 | J8: 38.311037 | K8: 38.311037 | L8: 373357 | M8: 373357 | N8: -3.1182875 | O8: -1.0417908 | P8: 851930 | Q8: 851930 | R8: 0.094575166 | S8: 0.094575166 | T8: 211.35106 | U8: 211.35106 | V8: 96.172297 | W8: 96.172297 | X8: 10.071213 | Y8: 10.375 | Z8: 10.375 | AA8: 0.57552587 | AB8: 0.57552587 | AC8: 0.61287173 | AD8: 72.918164 | AE8: 72.918164 | AF8: 4.4125673 | AG8: 4.4125673 | AH8: 242 | AI8: 363 | AJ8: 93 | AK8: 302 | AL8: 2 | AM8: =+AF8-AL8 -> 2.4125673
A9: 33694 | B9: 62.131083 | C9: 60.143593 | D9: 62.056834 | E9: 43.882111 | F9: 118.7579 | G9: 59.959978 | H9: 51.685557 | I9: 51.670967 | J9: 38.258535 | K9: 38.258535 | L9: 373317 | M9: 373317 | N9: -3.3500751 | O9: -1.1690213 | P9: 847165.67 | Q9: 847165.67 | R9: 0.097007586 | S9: 0.097007586 | T9: 215.27103 | U9: 215.27103 | V9: 95.797952 | W9: 95.797952 | X9: 10.079292 | Y9: 10.375 | Z9: 10.375 | AA9: 0.56924052 | AB9: 0.56924052 | AC9: 0.61394997 | AD9: 73.684026 | AE9: 73.684026 | AF9: 4.3453333 | AG9: 4.3453333 | AH9: 244 | AI9: 360 | AJ9: 91 | AK9: 305 | AL9: 2 | AM9: =+AF9-AL9 -> 2.3453333
A10: 33785 | B10: 62.416759 | C10: 60.420047 | D10: 63.194403 | E10: 44.452914 | F10: 118.72539 | G10: 59.723829 | H10: 52.427892 | I10: 51.90606 | J10: 38.383855 | K10: 38.383855 | L10: 372751 | M10: 372751 | N10: -3.1236345 | O10: -1.8203614 | P10: 847646.6 | Q10: 847646.6 | R10: 0.09785394 | S10: 0.09785394 | T10: 216.52634 | U10: 216.52634 | V10: 97.573482 | W10: 97.573482 | X10: 9.7404194 | Y10: 10.0471 | Z10: 10.0471 | AA10: 0.56506054 | AB10: 0.56506054 | AC10: 0.60791183 | AD10: 74.734655 | AE10: 74.734655 | AF10: 4.0467864 | AG10: 4.0467864 | AH10: 244 | AI10: 360 | AJ10: 91 | AK10: 305 | AL10: 2 | AM10: =+AF10-AL10 -> 2.0467864
A11: 33877 | B11: 62.691059 | C11: 60.685211 | D11: 63.067373 | E11: 44.967908 | F11: 118.80745 | G11: 59.567454 | H11: 51.973211 | I11: 52.023965 | J11: 38.275282 | K11: 38.275282 | L11: 374537 | M11: 374537 | N11: -3.3243309 | O11: -0.85749752 | P11: 840427.1 | Q11: 840427.1 | R11: 0.099370554 | S11: 0.099370554 | T11: 219.44681 | U11: 219.44681 | V11: 96.710815 | W11: 96.710815 | X11: 9.695813 | Y11: 9.7673 | Z11: 9.7673 | AA11: 0.56539814 | AB11: 0.56539814 | AC11: 0.60273627 | AD11: 75.563565 | AE11: 75.563565 | AF11: 3.8414337 | AG11: 3.8414337 | AH11: 244 | AI11: 360 | AJ11: 91 | AK11: 305 | AL11: 2 | AM11: =+AF11-AL11 -> 1.8414337
A12: 33969 | B12: 63.195466 | C12: 61.173856 | D12: 63.467567 | E12: 45.533479 | F12: 118.62097 | G12: 60.084592 | H12: 52.154689 | I12: 52.659248 | J12: 38.984401 | K12: 38.984401 | L12: 377418 | M12: 377418 | N12: -3.2279251 | O12: -0.27664328 | P12: 832788.39 | Q12: 832788.39 | R12: 0.10371119 | S12: 0.10371119 | T12: 221.35146 | U12: 221.35146 | V12: 84.845339 | W12: 84.845339 | X12: 7.1698732 | Y12: 7.5313 | Z12: 7.5313 | AA12: 0.59920423 | AB12: 0.59920423 | AC12: 0.64263116 | AD12: 76.644093 | AE12: 76.644093 | AF12: 3.5328715 | AG12: 3.5328715 | AH12: 244 | AI12: 360 | AJ12: 91 | AK12: 305 | AL12: 2 | AM12: =+AF12-AL12 -> 1.5328715
A13: 34059 | B13: 63.53193 | C13: 61.499755 | D13: 63.530914 | E13: 46.101573 | F13: 118.15539 | G13: 60.484175 | H13: 53.053856 | I13: 53.005409 | J13: 39.383108 | K13: 39.383108 | L13: 379370 | M13: 379370 | N13: -3.0780999 | O13: -0.54416477 | P13: 832300.53 | Q13: 832300.53 | R13: 0.10618491 | S13: 0.10618491 | T13: 221.58357 | U13: 221.58357 | V13: 83.282759 | W13: 83.282759 | X13: 5.9494269 | Y13: 6.129 | Z13: 6.129 | AA13: 0.62407768 | AB13: 0.62407768 | AC13: 0.67454707 | AD13: 77.756408 | AE13: 77.756408 | AF13: 3.0711828 | AG13: 3.0711828 | AH13: 228 | AI13: 343 | AJ13: 91 | AK13: 338 | AL13: 2 | AM13: =+AF13-AL13 -> 1.0711828
... A142: 45838 | B142: 137.87157 | C142: 137.87146 | D142: 138.04057 | E142: 142.47561 | F142: 122.70051 | G142: 140.78271 | H142: 144.80364 | I142: 144.36323 | J142: 152.26305 | K142: 153.38041 | L142: 705403 | M142: 705403 | N142: -0.53521004 | O142: -1.8925383 | P142: 1092607.1 | Q142: 1092607.1 | R142: 0.04660112 | S142: 0.04660112 | T142: 670.36599 | U142: 670.36599 | V142: 85.433745 | W142: 85.433745 | X142: 4.1790199 | Y142: 3.7371024 | Z142: 3.7425486 | AA142: 0.99181196 | AB142: 0.99106811 | AC142: 1.0097549 | AD142: 169.42098 | AE142: 169.42098 | AF142: 4.0110426 | AG142: 4.0110426 | AH142: 151.1486 | AI142: 286.3633 | AJ142: 61.6527 | AK142: 500.8354 | AL142: 2 | AM142: =+AF142-AL142 -> 2.0110426
A143: 45930 | B143: 139.17556 | C143: 139.17544 | D143: 138.97188 | E143: 143.83211 | F143: 123.18805 | G143: 142.64323 | H143: 146.02696 | I143: 146.17239 | J143: 153.78204 | K143: 152.77858 | L143: 706813.81 | M143: 706813.81 | O143: -1.6978608 | P143: 1088109.9 | Q143: 1088109.9 | R143: 0.048668948 | S143: 0.048668948 | T143: 674.78348 | U143: 675.06649 | V143: 84.985242 | W143: 84.985242 | X143: 3.9805726 | Y143: 3.623433 | Z143: 3.623433 | AA143: 0.98826679 | AB143: 0.98826679 | AC143: 1.006946 | AD143: 170.10292 | AE143: 170.10291 | AF143: 3.9691108 | AG143: 3.9691108 | AH143: 151.1486 | AI143: 286.3633 | AJ143: 61.6527 | AK143: 500.8354 | AL143: 2 | AM143: =+AF143-AL143 -> 1.9691108
A144: 46022 | B144: 139.91004 | C144: 139.90992 | D144: 139.85387 | E144: 144.83827 | F144: 123.51261 | G144: 144.14372 | H144: 146.88064 | I144: 147.33385 | J144: 153.89556 | K144: 154.08739 | L144: 708934.25 | M144: 708934.25 | O144: -1.8289475 | P144: 1089925.4 | Q144: 1089925.4 | R144: 0.049697693 | S144: 0.049697693 | U144: 680.79359 | W144: 84.479013 | Y144: 3.5100422 | Z144: 3.5100422 | AA144: 0.98263827 | AB144: 0.98263827 | AD144: 170.38249 | AE144: 170.38248 | AG144: 3.9221779 | AH144: 151.1486 | AI144: 286.3633 | AJ144: 61.6527 | AK144: 500.8354
A145: 46112 | D145: 140.96006 | H145: 148.75767 | I145: 0 | J145: 0 | K145: 152.38088 | M145: 711292.91 | O145: -1.7040186 | Q145: 1088841.3 | S145: 0.0504 | U145: 686.71173 | W145: 84.252156 | Y145: 3.4154219 | Z145: 3.4154219 | AB145: 0.97725801 | AD145: 170.76719 | AE145: 170.76718 | AG145: 3.4732572 | AH145: 146.37555 | AI145: 277.06973 | AJ145: 58.33398 | AK145: 518.22073
A146: 46203 | D146: 142.0057 | H146: 149.8334 | I146: 0 | J146: 0 | K146: 148.04947 | M146: 713598.35 | O146: -1.7237463 | Q146: 1089619.5 | S146: 0.050541252 | U146: 692.12433 | W146: 84.117539 | Y146: 3.3219454 | Z146: 3.3219454 | AB146: 0.9749504 | AD146: 171.28775 | AE146: 171.28774 | AG146: 3.2071262 | AH146: 146.73083 | AI146: 276.4363 | AJ146: 58.33497 | AK146: 518.4979
A147: 46295 | D147: 142.70719 | H147: 149.92516 | I147: 0 | J147: 0 | K147: 149.5711 | M147: 716034.92 | O147: -1.6558511 | Q147: 1090427.8 | S147: 0.050498257 | U147: 697.3824 | W147: 83.98531 | Y147: 3.3064318 | Z147: 3.3064318 | AB147: 0.97388427 | AD147: 172.08142 | AE147: 172.08141 | AG147: 2.9284517 | AH147: 146.73083 | AI147: 276.4363 | AJ147: 58.33497 | AK147: 518.4979
A148: 46387 | D148: 143.35098 | H148: 151.64689 | I148: 0 | J148: 0 | K148: 149.37929 | M148: 718746.04 | O148: -1.6089581 | Q148: 1092228.2 | S148: 0.050389561 | U148: 702.54561 | W148: 83.853892 | Y148: 3.3371672 | Z148: 3.3371672 | AB148: 0.97306004 | AD148: 172.82848 | AE148: 172.82847 | AG148: 2.7607717 | AH148: 146.73083 | AI148: 276.4363 | AJ148: 58.33497 | AK148: 518.4979
A149: 46477 | D149: 144.03329 | H149: 0 | I149: 0 | J149: 0 | K149: 148.75311 | M149: 721631.31 | O149: -1.5371047 | Q149: 1094167.4 | S149: 0.05021789 | U149: 707.66289 | W149: 83.722428 | Y149: 3.376846 | Z149: 3.376846 | AB149: 0.97240044 | AD149: 173.77928 | AE149: 173.77927 | AG149: 2.6830774 | AH149: 146.37555 | AI149: 277.06973 | AJ149: 58.33398 | AK149: 518.22073
A150: 46568 | D150: 144.76619 | H150: 0 | I150: 0 | J150: 0 | K150: 149.36955 | M150: 724747.91 | O150: -1.4586119 | Q150: 1096113.2 | S150: 0.05003043 | U150: 712.79819 | W150: 83.591451 | Y150: 3.4138167 | Z150: 3.4138167 | AB150: 0.97421349 | AD150: 174.72296 | AE150: 174.72296 | AG150: 2.6433548 | AH150: 146.73083 | AI150: 276.4363 | AJ150: 58.33497 | AK150: 518.4979
A151: 46660 | D151: 145.50721 | H151: 0 | I151: 0 | J151: 0 | K151: 149.91701 | M151: 727950.51 | O151: -1.3726282 | Q151: 1097963.2 | S151: 0.04974273 | U151: 717.99084 | W151: 83.462187 | Y151: 3.4440408 | Z151: 3.4440408 | AB151: 0.97436963 | AD151: 175.63827 | AE151: 175.63827 | AG151: 2.6218393 | AH151: 146.73083 | AI151: 276.4363 | AJ151: 58.33497 | AK151: 518.4979
A152: 46752 | D152: 146.26524 | H152: 0 | I152: 0 | J152: 0 | K152: 136.40861 | M152: 731300.17 | O152: -1.3276231 | Q152: 1100126.6 | S152: 0.049361609 | U152: 723.26555 | W152: 83.335501 | Y152: 3.469114 | Z152: 3.469114 | AB152: 0.97332131 | AD152: 176.37233 | AE152: 176.37234 | AG152: 2.609262 | AH152: 146.73083 | AI152: 276.4363 | AJ152: 58.33497 | AK152: 518.4979
A153: 46843 | D153: 147.00874 | H153: 0 | I153: 0 | J153: 0 | K153: 134.59702 | M153: 734695.69 | O153: -1.3352153 | Q153: 1103179.9 | S153: 0.048942373 | U153: 728.68905 | W153: 83.211438 | Y153: 3.4901568 | Z153: 3.4901568 | AB153: 0.97211634 | AD153: 177.09076 | AE153: 177.09077 | AG153: 2.6222316 | AH153: 146.37555 | AI153: 277.06973 | AJ153: 58.33398 | AK153: 518.22073
A154: 46934 | D154: 147.78016 | H154: 0 | I154: 0 | J154: 0 | K154: 133.93665 | M154: 738059.62 | O154: -1.2781854 | Q154: 1105659.2 | S154: 0.048451841 | U154: 734.32554 | W154: 83.089805 | Y154: 3.5168931 | Z154: 3.5168931 | AB154: 0.97121443 | AD154: 177.87613 | AE154: 177.87615 | AG154: 2.6420013 | AH154: 146.73083 | AI154: 276.4363 | AJ154: 58.33497 | AK154: 518.4979
A155: 47026 | D155: 148.54929 | H155: 0 | I155: 0 | J155: 0 | K155: 134.87225 | M155: 741431.62 | O155: -1.2382119 | Q155: 1108222.5 | S155: 0.047972324 | U155: 740.21052 | W155: 82.970359 | Y155: 3.5462896 | Z155: 3.5462896 | AB155: 0.97018549 | AD155: 178.61289 | AE155: 178.61291 | AG155: 2.6284768 | AH155: 146.73083 | AI155: 276.4363 | AJ155: 58.33497 | AK155: 518.4979
A156: 47118 | D156: 149.33243 | H156: 0 | I156: 0 | J156: 0 | K156: 135.45874 | M156: 744811.57 | O156: -1.1823681 | Q156: 1110769.1 | S156: 0.047406381 | U156: 746.35252 | W156: 82.852815 | Y156: 3.5778306 | Z156: 3.5778306 | AB156: 0.96942556 | AD156: 179.2077 | AE156: 179.20772 | AG156: 2.6276947 | AH156: 146.73083 | AI156: 276.4363 | AJ156: 58.33497 | AK156: 518.4979

Sheet datav1
A1: Date | B1: cpi | C1: cpi_a | D1: cpi_f | E1: services | F1: core_gds | G1: food | H1: food_at | I1: energy | J1: gdpkp | K1: gdpkp_f | L1: capu | M1: capu_f | N1: hrs | O1: hrs_f | P1: unemp | Q1: unemp_f | R1: wage | S1: wage_f | T1: eer | U1: eer_f | V1: ois_rate | W1: bank_rate | X1: bank_rate_f | Y1: pmdef | Z1: pmdef_f | AA1: cpif | AB1: cpif_f | AC1: exp_cpi
A2: 33054 | B2: 55.216192 | C2: 53.449601 | D2: 55.931591 | E2: 37.291624 | F2: 109.4919 | G2: 55.346352 | H2: 46.757461 | I2: 33.809155 | J2: 381997 | K2: 381997 | L2: -1.1483808 | M2: 0.93596216 | N2: 906588.84 | O2: 906588.84 | P2: 0.069184781 | Q2: 0.069184781 | R2: 189.32838 | S2: 189.32838 | T2: 93.068646 | U2: 93.068646 | V2: 14.519134 | W2: 14.875 | X2: 14.875 | Y2: 0.57773628 | Z2: 0.57773628 | AA2: 67.416856 | AB2: 67.416856 | AC2: 8.6373834
A3: 33146 | B3: 56.369272 | C3: 54.565685 | D3: 56.730638 | E3: 38.226404 | F3: 110.77076 | G3: 56.069625 | H3: 46.959972 | I3: 35.502014 | J3: 377831 | K3: 377831 | L3: -1.7358221 | M3: -0.79049292 | N3: 901813.5 | O3: 901813.5 | P3: 0.070779647 | Q3: 0.070779647 | R3: 193.61239 | S3: 193.61239 | T3: 99.445968 | U3: 99.445968 | V3: 14.377204 | W3: 14.875 | X3: 14.875 | Y3: 0.55930606 | Z3: 0.55930606 | AA3: 68.109698 | AB3: 68.109698 | AC3: 9.1039566
A4: 33238 | B4: 57.494732 | C4: 55.655628 | D4: 57.774359 | E4: 39.201503 | F4: 112.05037 | G4: 57.003542 | H4: 47.50451 | I4: 36.723481 | J4: 375916 | K4: 375916 | L4: -2.1830843 | M4: -1.1706663 | N4: 892410.87 | O4: 892410.87 | P4: 0.074650616 | Q4: 0.074650616 | R4: 197.31141 | S4: 197.31141 | T4: 99.670858 | U4: 99.670858 | V4: 13.268016 | W4: 13.9531 | X4: 13.9531 | Y4: 0.56615029 | Z4: 0.56615029 | AA4: 69.42033 | AB4: 69.42033 | AC4: 7.4794737
A5: 33328 | B5: 58.131185 | C5: 56.271618 | D5: 58.016017 | E5: 40.047704 | F5: 112.98292 | G5: 57.575944 | H5: 48.473466 | I5: 36.121607 | J5: 374060 | K5: 374060 | L5: -2.9343664 | M5: -1.255856 | N5: 881370.83 | O5: 881370.83 | P5: 0.079969483 | Q5: 0.079969483 | R5: 199.57143 | S5: 199.57143 | T5: 99.118131 | U5: 99.118131 | V5: 12.723411 | W5: 13.3992 | X5: 13.3992 | Y5: 0.56293382 | Z5: 0.56293382 | AA5: 70.402484 | AB5: 70.402484 | AC5: 7.1724561
A6: 33419 | B6: 59.827705 | C6: 57.9136 | D6: 60.59482 | E6: 41.709306 | F6: 115.1372 | G6: 58.344421 | H6: 50.505217 | I6: 37.362098 | J6: 373608 | K6: 373608 | L6: -3.3312328 | M6: -1.273024 | N6: 869788.47 | O6: 869788.47 | P6: 0.086627038 | Q6: 0.086627038 | R6: 204.08804 | S6: 204.08804 | T6: 96.421142 | U6: 96.421142 | V6: 11.097574 | W6: 11.7379 | X6: 11.7379 | Y6: 0.57235316 | Z6: 0.57235316 | AA6: 71.079089 | AB6: 71.079089 | AC6: 5.5856456
A7: 33511 | B7: 60.749441 | C7: 58.805692 | D7: 61.129417 | E7: 42.478114 | F7: 116.63678 | G7: 58.886712 | H7: 50.449029 | I7: 38.223615 | J7: 372878 | K7: 372878 | L7: -3.4757524 | M7: -1.2520863 | N7: 859520.46 | O7: 859520.46 | P7: 0.09159133 | Q7: 0.09159133 | R7: 208.2244 | S7: 208.2244 | T7: 95.722653 | U7: 95.722653 | V7: 10.282062 | W7: 10.7981 | X7: 10.7981 | Y7: 0.58356049 | Z7: 0.58356049 | AA7: 71.94639 | AB7: 71.94639 | AC7: 4.6085185
A8: 33603 | B8: 61.5371 | C8: 59.568663 | D8: 61.822885 | E8: 43.254296 | F8: 117.83569 | G8: 59.515813 | H8: 50.749747 | I8: 38.311037 | J8: 373357 | K8: 373357 | L8: -3.1182875 | M8: -1.0417908 | N8: 851930 | O8: 851930 | P8: 0.094575166 | Q8: 0.094575166 | R8: 211.35106 | S8: 211.35106 | T8: 96.172297 | U8: 96.172297 | V8: 10.071213 | W8: 10.375 | X8: 10.375 | Y8: 0.57552587 | Z8: 0.57552587 | AA8: 72.918164 | AB8: 72.918164 | AC8: 4.4125673
A9: 33694 | B9: 62.131083 | C9: 60.143593 | D9: 62.056834 | E9: 43.882111 | F9: 118.7579 | G9: 59.959978 | H9: 51.685557 | I9: 38.258535 | J9: 373317 | K9: 373317 | L9: -3.3500751 | M9: -1.1690213 | N9: 847165.67 | O9: 847165.67 | P9: 0.097007586 | Q9: 0.097007586 | R9: 215.27103 | S9: 215.27103 | T9: 95.797952 | U9: 95.797952 | V9: 10.079292 | W9: 10.375 | X9: 10.375 | Y9: 0.56924052 | Z9: 0.56924052 | AA9: 73.684026 | AB9: 73.684026 | AC9: 4.3453333
A10: 33785 | B10: 62.416759 | C10: 60.420047 | D10: 63.194403 | E10: 44.452914 | F10: 118.72539 | G10: 59.723829 | H10: 52.427892 | I10: 38.383855 | J10: 372751 | K10: 372751 | L10: -3.1236345 | M10: -1.8203614 | N10: 847646.6 | O10: 847646.6 | P10: 0.09785394 | Q10: 0.09785394 | R10: 216.52634 | S10: 216.52634 | T10: 97.573482 | U10: 97.573482 | V10: 9.7404194 | W10: 10.0471 | X10: 10.0471 | Y10: 0.56506054 | Z10: 0.56506054 | AA10: 74.734655 | AB10: 74.734655 | AC10: 4.0467864
A11: 33877 | B11: 62.691059 | C11: 60.685211 | D11: 63.067373 | E11: 44.967908 | F11: 118.80745 | G11: 59.567454 | H11: 51.973211 | I11: 38.275282 | J11: 374537 | K11: 374537 | L11: -3.3243309 | M11: -0.85749752 | N11: 840427.1 | O11: 840427.1 | P11: 0.099370554 | Q11: 0.099370554 | R11: 219.44681 | S11: 219.44681 | T11: 96.710815 | U11: 96.710815 | V11: 9.695813 | W11: 9.7673 | X11: 9.7673 | Y11: 0.56539814 | Z11: 0.56539814 | AA11: 75.563565 | AB11: 75.563565 | AC11: 3.8414337
A12: 33969 | B12: 63.195466 | C12: 61.173856 | D12: 63.467567 | E12: 45.533479 | F12: 118.62097 | G12: 60.084592 | H12: 52.154689 | I12: 38.984401 | J12: 377418 | K12: 377418 | L12: -3.2279251 | M12: -0.27664328 | N12: 832788.39 | O12: 832788.39 | P12: 0.10371119 | Q12: 0.10371119 | R12: 221.35146 | S12: 221.35146 | T12: 84.845339 | U12: 84.845339 | V12: 7.1698732 | W12: 7.5313 | X12: 7.5313 | Y12: 0.59920423 | Z12: 0.59920423 | AA12: 76.644093 | AB12: 76.644093 | AC12: 3.5328715
A13: 34059 | B13: 63.53193 | C13: 61.499755 | D13: 63.530914 | E13: 46.101573 | F13: 118.15539 | G13: 60.484175 | H13: 53.053856 | I13: 39.383108 | J13: 379370 | K13: 379370 | L13: -3.0780999 | M13: -0.54416477 | N13: 832300.53 | O13: 832300.53 | P13: 0.10618491 | Q13: 0.10618491 | R13: 221.58357 | S13: 221.58357 | T13: 83.282759 | U13: 83.282759 | V13: 5.9494269 | W13: 6.129 | X13: 6.129 | Y13: 0.62407768 | Z13: 0.62407768 | AA13: 77.756408 | AB13: 77.756408 | AC13: 3.0711828
... A142: 45838 | B142: 137.87157 | C142: 137.87146 | D142: 138.04057 | E142: 142.47561 | F142: 122.70051 | G142: 140.78271 | H142: 144.80364 | I142: 152.26215 | J142: 705403 | K142: 705403 | L142: -0.53521004 | M142: -1.8925383 | N142: 1092607.1 | O142: 1092607.1 | P142: 0.04660112 | Q142: 0.04660112 | R142: 670.36599 | S142: 670.36599 | T142: 85.433745 | U142: 85.433745 | V142: 4.1790199 | W142: 3.7371024 | X142: 3.7425486 | Y142: 0.99181196 | Z142: 0.99106811 | AA142: 169.42098 | AB142: 169.42098 | AC142: 4.0110426
A143: 45930 | B143: 139.17556 | C143: 139.17544 | D143: 138.97188 | E143: 143.83211 | F143: 123.18805 | G143: 142.64323 | H143: 146.02696 | I143: 153.77967 | J143: 706813.81 | K143: 706813.81 | M143: -1.6978608 | N143: 1088109.9 | O143: 1088109.9 | P143: 0.048668948 | Q143: 0.048668948 | R143: 674.78348 | S143: 675.06649 | T143: 84.985242 | U143: 84.985242 | V143: 3.9805726 | W143: 3.623433 | X143: 3.623433 | Y143: 0.98826679 | Z143: 0.98826679 | AA143: 170.10292 | AB143: 170.10291 | AC143: 3.9691108
A144: 46022 | B144: 139.91004 | C144: 139.90992 | D144: 139.85387 | E144: 144.83827 | F144: 123.51261 | G144: 144.14372 | H144: 147.49282 | I144: 153.60509 | J144: 708934.25 | K144: 708934.25 | M144: -1.8289475 | N144: 1089925.4 | O144: 1089925.4 | P144: 0.049697693 | Q144: 0.049697693 | S144: 680.79359 | U144: 84.479013 | W144: 3.5100422 | X144: 3.5100422 | Y144: 0.98263827 | Z144: 0.98263827 | AA144: 170.38249 | AB144: 170.38248
A145: 46112 | D145: 139.85387 | K145: 711292.91 | M145: -1.7040186 | O145: 1088841.3 | Q145: 0.0504 | S145: 686.71173 | U145: 84.252156 | W145: 3.4154219 | X145: 3.4154219 | Z145: 0.97725801 | AA145: 170.76719 | AB145: 170.76718
A146: 46203 | D146: 139.85387 | K146: 713598.35 | M146: -1.7237463 | O146: 1089619.5 | Q146: 0.050541252 | S146: 692.12433 | U146: 84.117539 | W146: 3.3219454 | X146: 3.3219454 | Z146: 0.9749504 | AA146: 171.28775 | AB146: 171.28774
A147: 46295 | D147: 139.85387 | K147: 716034.92 | M147: -1.6558511 | O147: 1090427.8 | Q147: 0.050498257 | S147: 697.3824 | U147: 83.98531 | W147: 3.3064318 | X147: 3.3064318 | Z147: 0.97388427 | AA147: 172.08142 | AB147: 172.08141
A148: 46387 | D148: 139.85387 | K148: 718746.04 | M148: -1.6089581 | O148: 1092228.2 | Q148: 0.050389561 | S148: 702.54561 | U148: 83.853892 | W148: 3.3371672 | X148: 3.3371672 | Z148: 0.97306004 | AA148: 172.82848 | AB148: 172.82847
A149: 46477 | D149: 139.85387 | K149: 721631.31 | M149: -1.5371047 | O149: 1094167.4 | Q149: 0.05021789 | S149: 707.66289 | U149: 83.722428 | W149: 3.376846 | X149: 3.376846 | Z149: 0.97240044 | AA149: 173.77928 | AB149: 173.77927
A150: 46568 | D150: 139.85387 | K150: 724747.91 | M150: -1.4586119 | O150: 1096113.2 | Q150: 0.05003043 | S150: 712.79819 | U150: 83.591451 | W150: 3.4138167 | X150: 3.4138167 | Z150: 0.97421349 | AA150: 174.72296 | AB150: 174.72296
A151: 46660 | D151: 139.85387 | K151: 727950.51 | M151: -1.3726282 | O151: 1097963.2 | Q151: 0.04974273 | S151: 717.99084 | U151: 83.462187 | W151: 3.4440408 | X151: 3.4440408 | Z151: 0.97436963 | AA151: 175.63827 | AB151: 175.63827
A152: 46752 | D152: 139.85387 | K152: 731300.17 | M152: -1.3276231 | O152: 1100126.6 | Q152: 0.049361609 | S152: 723.26555 | U152: 83.335501 | W152: 3.469114 | X152: 3.469114 | Z152: 0.97332131 | AA152: 176.37233 | AB152: 176.37234
A153: 46843 | D153: 139.85387 | K153: 734695.69 | M153: -1.3352153 | O153: 1103179.9 | Q153: 0.048942373 | S153: 728.68905 | U153: 83.211438 | W153: 3.4901568 | X153: 3.4901568 | Z153: 0.97211634 | AA153: 177.09076 | AB153: 177.09077
A154: 46934 | D154: 139.85387 | K154: 738059.62 | M154: -1.2781854 | O154: 1105659.2 | Q154: 0.048451841 | S154: 734.32554 | U154: 83.089805 | W154: 3.5168931 | X154: 3.5168931 | Z154: 0.97121443 | AA154: 177.87613 | AB154: 177.87615
A155: 47026 | D155: 139.85387 | K155: 741431.62 | M155: -1.2382119 | O155: 1108222.5 | Q155: 0.047972324 | S155: 740.21052 | U155: 82.970359 | W155: 3.5462896 | X155: 3.5462896 | Z155: 0.97018549 | AA155: 178.61289 | AB155: 178.61291
A156: 47118 | D156: 139.85387 | K156: 744811.57 | M156: -1.1823681 | O156: 1110769.1 | Q156: 0.047406381 | S156: 746.35252 | U156: 82.852815 | W156: 3.5778306 | X156: 3.5778306 | Z156: 0.96942556 | AA156: 179.2077 | AB156: 179.20772

Sheet data_1
C1: T | D1: T | E1: T | F1: T | G1: T | H1: T | I1: T | K1: T | M1: T | N1: T | O1: L | P1: L | Q1: T | R1: T | S1: L | T1: L | U1: T | V1: T | W1: L | Y1: L | Z1: L | AA1: L | AB1: T | AD1: T | AE1: T | AF1: L | AH1: T | AJ1: L
C2: cpi_qoq | D2: cpi_a_qoq | E2: cpi_f_qoq
B3: Date | C3: =Data_FAME!B9 -> cpi | D3: =Data_FAME!C9 -> cpi_a | E3: =Data_FAME!D9 -> cpi_f | F3: =Data_FAME!F9 -> services | G3: =Data_FAME!H9 -> core_gds | H3: =Data_FAME!J9 -> food | I3: ='Data_FAME (2)'!L9 -> food_at_nsa | J3: ='Data_FAME (2)'!M9 -> food_at | K3: =Data_FAME!N9 -> energy | M3: =Data_FAME!Q9 -> gdpkp | N3: =Data_FAME!R9 -> gdpkp_f | O3: =Data_FAME!T9 -> capu | P3: =Data_FAME!U9 -> capu_f | Q3: =Data_FAME!W9 -> hrs | R3: =Data_FAME!X9 -> hrs_f | S3: =Data_FAME!Z9 -> unemp | T3: =Data_FAME!AA9 -> unemp_f | U3: =Data_FAME!AD9 -> wage | V3: =Data_FAME!AE9 -> wage_f | W3: =Data_FAME!AH9 -> eer | Y3: =Data_FAME!AL9 -> ois_rate | Z3: =Data_FAME!AN9 -> bank_rate | AA3: =Data_FAME!AO9 -> bank_rate_f | AB3: =Data_FAME!AR9 -> pmdef | AC3: =Data_FAME!AT9 -> pmdef_xf | AD3: =Data_FAME!AV9 -> cpif | AE3: =Data_FAME!AW9 -> cpif_f | AF3: =Data_FAME!BA9 -> inf_exp | AG3: N25_inf_exp_FIN | AH3: N25_pmdef_FIN | AI3: N25_pmdef_FIN | AJ3: =Data_FAME!AI9 -> eer_f | AK3: f26_inf_exp | AM3: fat_wgt | AN3: cf_wgt | AO3: e_wgt | AP3: s_wgt
B4: 32963 | C4: =Data_FAME!B11 -> 0 | D4: =Data_FAME!C11 -> 0 | E4: =Data_FAME!D11 -> 54.233282 | F4: =Data_FAME!F11 -> 0 | G4: =Data_FAME!H11 -> 0 | H4: =Data_FAME!J11 -> 0 | I4: ='Data_FAME (2)'!L11 -> 45.323672 | J4: ='Data_FAME (2)'!M11 -> 0 | K4: ='Data_FAME (2)'!O11 -> 0 | M4: =Data_FAME!Q11 -> 379458 | N4: =Data_FAME!R11 -> 379458 | O4: =Data_FAME!T11 -> -0.70757743 | P4: =Data_FAME!U11 -> 0.97333792 | Q4: =Data_FAME!W11 -> 908133 | R4: =Data_FAME!X11 -> 908133 | S4: =Data_FAME!Z11 -> 0.069332964 | T4: =Data_FAME!AA11 -> 0.069332964 | U4: =Data_FAME!AD11 -> 183.54771 | V4: =Data_FAME!AE11 -> 183.54771 | W4: =Data_FAME!AH11 -> 92.432746 | Y4: =Data_FAME!AL11 -> 0 | Z4: =Data_FAME!AN11 -> 14.875 | AA4: =Data_FAME!AO11 -> 14.875 | AB4: =Data_FAME!AR11 -> 0.57372025 | AC4: =Data_FAME!AT11 -> 0.60812747 | AD4: =Data_FAME!AV11 -> 66.518783 | AE4: =Data_FAME!AW11 -> 66.518783 | AF4: =Data_FAME!BB11 -> 7.7756322 | AG4: =Data_FAME!BB11 -> 7.7756322 | AH4: =Data_FAME!AS11 -> 0.57372025 | AI4: ='Data_FAME (2)'!P11 -> 0 | AJ4: =Data_FAME!AI11 -> 92.432746 | AM4: ='Data_FAME (2)'!BF11 -> 251 | AN4: ='Data_FAME (2)'!BG11 -> 359 | AO4: ='Data_FAME (2)'!BH11 -> 96 | AP4: ='Data_FAME (2)'!BI11 -> 294
B5: =Data_FAME!A12 -> 33054 | C5: =Data_FAME!B12 -> 55.216192 | D5: =Data_FAME!C12 -> 53.449601 | E5: =Data_FAME!D12 -> 55.931591 | F5: =Data_FAME!F12 -> 37.291624 | G5: =Data_FAME!H12 -> 109.4919 | H5: =Data_FAME!J12 -> 55.346352 | I5: ='Data_FAME (2)'!L12 -> 46.757461 | J5: ='Data_FAME (2)'!M12 -> 46.254605 | K5: ='Data_FAME (2)'!O12 -> 33.809155 | M5: =Data_FAME!Q12 -> 381997 | N5: =Data_FAME!R12 -> 381997 | O5: =Data_FAME!T12 -> -1.1483808 | P5: =Data_FAME!U12 -> 0.93596216 | Q5: =Data_FAME!W12 -> 906588.84 | R5: =Data_FAME!X12 -> 906588.84 | S5: =Data_FAME!Z12 -> 0.069184781 | T5: =Data_FAME!AA12 -> 0.069184781 | U5: =Data_FAME!AD12 -> 189.32838 | V5: =Data_FAME!AE12 -> 189.32838 | W5: =Data_FAME!AH12 -> 93.068646 | Y5: =Data_FAME!AL12 -> 14.519134 | Z5: =Data_FAME!AN12 -> 14.875 | AA5: =Data_FAME!AO12 -> 14.875 | AB5: =Data_FAME!AR12 -> 0.57773628 | AC5: =Data_FAME!AT12 -> 0.60985266 | AD5: =Data_FAME!AV12 -> 67.416856 | AE5: =Data_FAME!AW12 -> 67.416856 | AF5: =Data_FAME!BB12 -> 8.6373834 | AG5: =Data_FAME!BB12 -> 8.6373834 | AH5: =Data_FAME!AS12 -> 0.57773628 | AI5: ='Data_FAME (2)'!P12 -> 33.809155 | AJ5: =Data_FAME!AI12 -> 93.068646 | AM5: ='Data_FAME (2)'!BF12 -> 251 | AN5: ='Data_FAME (2)'!BG12 -> 359 | AO5: ='Data_FAME (2)'!BH12 -> 96 | AP5: ='Data_FAME (2)'!BI12 -> 294
B6: =Data_FAME!A13 -> 33146 | C6: =Data_FAME!B13 -> 56.369272 | D6: =Data_FAME!C13 -> 54.565685 | E6: =Data_FAME!D13 -> 56.730638 | F6: =Data_FAME!F13 -> 38.226404 | G6: =Data_FAME!H13 -> 110.77076 | H6: =Data_FAME!J13 -> 56.069625 | I6: ='Data_FAME (2)'!L13 -> 46.959972 | J6: ='Data_FAME (2)'!M13 -> 47.031491 | K6: ='Data_FAME (2)'!O13 -> 35.502014 | M6: =Data_FAME!Q13 -> 377831 | N6: =Data_FAME!R13 -> 377831 | O6: =Data_FAME!T13 -> -1.7358221 | P6: =Data_FAME!U13 -> -0.79049292 | Q6: =Data_FAME!W13 -> 901813.5 | R6: =Data_FAME!X13 -> 901813.5 | S6: =Data_FAME!Z13 -> 0.070779647 | T6: =Data_FAME!AA13 -> 0.070779647 | U6: =Data_FAME!AD13 -> 193.61239 | V6: =Data_FAME!AE13 -> 193.61239 | W6: =Data_FAME!AH13 -> 99.445968 | Y6: =Data_FAME!AL13 -> 14.377204 | Z6: =Data_FAME!AN13 -> 14.875 | AA6: =Data_FAME!AO13 -> 14.875 | AB6: =Data_FAME!AR13 -> 0.55930606 | AC6: =Data_FAME!AT13 -> 0.59130693 | AD6: =Data_FAME!AV13 -> 68.109698 | AE6: =Data_FAME!AW13 -> 68.109698 | AF6: =Data_FAME!BB13 -> 9.1039566 | AG6: =Data_FAME!BB13 -> 9.1039566 | AH6: =Data_FAME!AS13 -> 0.55930606 | AI6: ='Data_FAME (2)'!P13 -> 35.502014 | AJ6: =Data_FAME!AI13 -> 99.445968 | AM6: ='Data_FAME (2)'!BF13 -> 251 | AN6: ='Data_FAME (2)'!BG13 -> 359 | AO6: ='Data_FAME (2)'!BH13 -> 96 | AP6: ='Data_FAME (2)'!BI13 -> 294
B7: =Data_FAME!A14 -> 33238 | C7: =Data_FAME!B14 -> 57.494732 | D7: =Data_FAME!C14 -> 55.655628 | E7: =Data_FAME!D14 -> 57.774359 | F7: =Data_FAME!F14 -> 39.201503 | G7: =Data_FAME!H14 -> 112.05037 | H7: =Data_FAME!J14 -> 57.003542 | I7: ='Data_FAME (2)'!L14 -> 47.50451 | J7: ='Data_FAME (2)'!M14 -> 47.936474 | K7: ='Data_FAME (2)'!O14 -> 36.723481 | M7: =Data_FAME!Q14 -> 375916 | N7: =Data_FAME!R14 -> 375916 | O7: =Data_FAME!T14 -> -2.1830843 | P7: =Data_FAME!U14 -> -1.1706663 | Q7: =Data_FAME!W14 -> 892410.87 | R7: =Data_FAME!X14 -> 892410.87 | S7: =Data_FAME!Z14 -> 0.074650616 | T7: =Data_FAME!AA14 -> 0.074650616 | U7: =Data_FAME!AD14 -> 197.31141 | V7: =Data_FAME!AE14 -> 197.31141 | W7: =Data_FAME!AH14 -> 99.670858 | Y7: =Data_FAME!AL14 -> 13.268016 | Z7: =Data_FAME!AN14 -> 13.9531 | AA7: =Data_FAME!AO14 -> 13.9531 | AB7: =Data_FAME!AR14 -> 0.56615029 | AC7: =Data_FAME!AT14 -> 0.5885035 | AD7: =Data_FAME!AV14 -> 69.42033 | AE7: =Data_FAME!AW14 -> 69.42033 | AF7: =Data_FAME!BB14 -> 7.4794737 | AG7: =Data_FAME!BB14 -> 7.4794737 | AH7: =Data_FAME!AS14 -> 0.56615029 | AI7: ='Data_FAME (2)'!P14 -> 36.723481 | AJ7: =Data_FAME!AI14 -> 99.670858 | AM7: ='Data_FAME (2)'!BF14 -> 251 | AN7: ='Data_FAME (2)'!BG14 -> 359 | AO7: ='Data_FAME (2)'!BH14 -> 96 | AP7: ='Data_FAME (2)'!BI14 -> 294
B8: =Data_FAME!A15 -> 33328 | C8: =Data_FAME!B15 -> 58.131185 | D8: =Data_FAME!C15 -> 56.271618 | E8: =Data_FAME!D15 -> 58.016017 | F8: =Data_FAME!F15 -> 40.047704 | G8: =Data_FAME!H15 -> 112.98292 | H8: =Data_FAME!J15 -> 57.575944 | I8: ='Data_FAME (2)'!L15 -> 48.473466 | J8: ='Data_FAME (2)'!M15 -> 48.483131 | K8: ='Data_FAME (2)'!O15 -> 36.121607 | M8: =Data_FAME!Q15 -> 374060 | N8: =Data_FAME!R15 -> 374060 | O8: =Data_FAME!T15 -> -2.9343664 | P8: =Data_FAME!U15 -> -1.255856 | Q8: =Data_FAME!W15 -> 881370.83 | R8: =Data_FAME!X15 -> 881370.83 | S8: =Data_FAME!Z15 -> 0.079969483 | T8: =Data_FAME!AA15 -> 0.079969483 | U8: =Data_FAME!AD15 -> 199.57143 | V8: =Data_FAME!AE15 -> 199.57143 | W8: =Data_FAME!AH15 -> 99.118131 | Y8: =Data_FAME!AL15 -> 12.723411 | Z8: =Data_FAME!AN15 -> 13.3992 | AA8: =Data_FAME!AO15 -> 13.3992 | AB8: =Data_FAME!AR15 -> 0.56293382 | AC8: =Data_FAME!AT15 -> 0.59734507 | AD8: =Data_FAME!AV15 -> 70.402484 | AE8: =Data_FAME!AW15 -> 70.402484 | AF8: =Data_FAME!BB15 -> 7.1724561 | AG8: =Data_FAME!BB15 -> 7.1724561 | AH8: =Data_FAME!AS15 -> 0.56293382 | AI8: ='Data_FAME (2)'!P15 -> 36.121607 | AJ8: =Data_FAME!AI15 -> 99.118131 | AM8: ='Data_FAME (2)'!BF15 -> 242 | AN8: ='Data_FAME (2)'!BG15 -> 363 | AO8: ='Data_FAME (2)'!BH15 -> 93 | AP8: ='Data_FAME (2)'!BI15 -> 302
B9: =Data_FAME!A16 -> 33419 | C9: =Data_FAME!B16 -> 59.827705 | D9: =Data_FAME!C16 -> 57.9136 | E9: =Data_FAME!D16 -> 60.59482 | F9: =Data_FAME!F16 -> 41.709306 | G9: =Data_FAME!H16 -> 115.1372 | H9: =Data_FAME!J16 -> 58.344421 | I9: ='Data_FAME (2)'!L16 -> 50.505217 | J9: ='Data_FAME (2)'!M16 -> 49.975838 | K9: ='Data_FAME (2)'!O16 -> 37.362098 | M9: =Data_FAME!Q16 -> 373608 | N9: =Data_FAME!R16 -> 373608 | O9: =Data_FAME!T16 -> -3.3312328 | P9: =Data_FAME!U16 -> -1.273024 | Q9: =Data_FAME!W16 -> 869788.47 | R9: =Data_FAME!X16 -> 869788.47 | S9: =Data_FAME!Z16 -> 0.086627038 | T9: =Data_FAME!AA16 -> 0.086627038 | U9: =Data_FAME!AD16 -> 204.08804 | V9: =Data_FAME!AE16 -> 204.08804 | W9: =Data_FAME!AH16 -> 96.421142 | Y9: =Data_FAME!AL16 -> 11.097574 | Z9: =Data_FAME!AN16 -> 11.7379 | AA9: =Data_FAME!AO16 -> 11.7379 | AB9: =Data_FAME!AR16 -> 0.57235316 | AC9: =Data_FAME!AT16 -> 0.60942136 | AD9: =Data_FAME!AV16 -> 71.079089 | AE9: =Data_FAME!AW16 -> 71.079089 | AF9: =Data_FAME!BB16 -> 5.5856456 | AG9: =Data_FAME!BB16 -> 5.5856456 | AH9: =Data_FAME!AS16 -> 0.57235316 | AI9: ='Data_FAME (2)'!P16 -> 37.362098 | AJ9: =Data_FAME!AI16 -> 96.421142 | AM9: ='Data_FAME (2)'!BF16 -> 242 | AN9: ='Data_FAME (2)'!BG16 -> 363 | AO9: ='Data_FAME (2)'!BH16 -> 93 | AP9: ='Data_FAME (2)'!BI16 -> 302
B10: =Data_FAME!A17 -> 33511 | C10: =Data_FAME!B17 -> 60.749441 | D10: =Data_FAME!C17 -> 58.805692 | E10: =Data_FAME!D17 -> 61.129417 | F10: =Data_FAME!F17 -> 42.478114 | G10: =Data_FAME!H17 -> 116.63678 | H10: =Data_FAME!J17 -> 58.886712 | I10: ='Data_FAME (2)'!L17 -> 50.449029 | J10: ='Data_FAME (2)'!M17 -> 50.515686 | K10: ='Data_FAME (2)'!O17 -> 38.223615 | M10: =Data_FAME!Q17 -> 372878 | N10: =Data_FAME!R17 -> 372878 | O10: =Data_FAME!T17 -> -3.4757524 | P10: =Data_FAME!U17 -> -1.2520863 | Q10: =Data_FAME!W17 -> 859520.46 | R10: =Data_FAME!X17 -> 859520.46 | S10: =Data_FAME!Z17 -> 0.09159133 | T10: =Data_FAME!AA17 -> 0.09159133 | U10: =Data_FAME!AD17 -> 208.2244 | V10: =Data_FAME!AE17 -> 208.2244 | W10: =Data_FAME!AH17 -> 95.722653 | Y10: =Data_FAME!AL17 -> 10.282062 | Z10: =Data_FAME!AN17 -> 10.7981 | AA10: =Data_FAME!AO17 -> 10.7981 | AB10: =Data_FAME!AR17 -> 0.58356049 | AC10: =Data_FAME!AT17 -> 0.61934117 | AD10: =Data_FAME!AV17 -> 71.94639 | AE10: =Data_FAME!AW17 -> 71.94639 | AF10: =Data_FAME!BB17 -> 4.6085185 | AG10: =Data_FAME!BB17 -> 4.6085185 | AH10: =Data_FAME!AS17 -> 0.58356049 | AI10: ='Data_FAME (2)'!P17 -> 38.223615 | AJ10: =Data_FAME!AI17 -> 95.722653 | AM10: ='Data_FAME (2)'!BF17 -> 242 | AN10: ='Data_FAME (2)'!BG17 -> 363 | AO10: ='Data_FAME (2)'!BH17 -> 93 | AP10: ='Data_FAME (2)'!BI17 -> 302
B11: =Data_FAME!A18 -> 33603 | C11: =Data_FAME!B18 -> 61.5371 | D11: =Data_FAME!C18 -> 59.568663 | E11: =Data_FAME!D18 -> 61.822885 | F11: =Data_FAME!F18 -> 43.254296 | G11: =Data_FAME!H18 -> 117.83569 | H11: =Data_FAME!J18 -> 59.515813 | I11: ='Data_FAME (2)'!L18 -> 50.749747 | J11: ='Data_FAME (2)'!M18 -> 51.223588 | K11: ='Data_FAME (2)'!O18 -> 38.311037 | M11: =Data_FAME!Q18 -> 373357 | N11: =Data_FAME!R18 -> 373357 | O11: =Data_FAME!T18 -> -3.1182875 | P11: =Data_FAME!U18 -> -1.0417908 | Q11: =Data_FAME!W18 -> 851930 | R11: =Data_FAME!X18 -> 851930 | S11: =Data_FAME!Z18 -> 0.094575166 | T11: =Data_FAME!AA18 -> 0.094575166 | U11: =Data_FAME!AD18 -> 211.35106 | V11: =Data_FAME!AE18 -> 211.35106 | W11: =Data_FAME!AH18 -> 96.172297 | Y11: =Data_FAME!AL18 -> 10.071213 | Z11: =Data_FAME!AN18 -> 10.375 | AA11: =Data_FAME!AO18 -> 10.375 | AB11: =Data_FAME!AR18 -> 0.57552587 | AC11: =Data_FAME!AT18 -> 0.61287173 | AD11: =Data_FAME!AV18 -> 72.918164 | AE11: =Data_FAME!AW18 -> 72.918164 | AF11: =Data_FAME!BB18 -> 4.4125673 | AG11: =Data_FAME!BB18 -> 4.4125673 | AH11: =Data_FAME!AS18 -> 0.57552587 | AI11: ='Data_FAME (2)'!P18 -> 38.311037 | AJ11: =Data_FAME!AI18 -> 96.172297 | AM11: ='Data_FAME (2)'!BF18 -> 242 | AN11: ='Data_FAME (2)'!BG18 -> 363 | AO11: ='Data_FAME (2)'!BH18 -> 93 | AP11: ='Data_FAME (2)'!BI18 -> 302
B12: =Data_FAME!A19 -> 33694 | C12: =Data_FAME!B19 -> 62.131083 | D12: =Data_FAME!C19 -> 60.143593 | E12: =Data_FAME!D19 -> 62.056834 | F12: =Data_FAME!F19 -> 43.882111 | G12: =Data_FAME!H19 -> 118.7579 | H12: =Data_FAME!J19 -> 59.959978 | I12: ='Data_FAME (2)'!L19 -> 51.685557 | J12: ='Data_FAME (2)'!M19 -> 51.670967 | K12: ='Data_FAME (2)'!O19 -> 38.258535 | M12: =Data_FAME!Q19 -> 373317 | N12: =Data_FAME!R19 -> 373317 | O12: =Data_FAME!T19 -> -3.3500751 | P12: =Data_FAME!U19 -> -1.1690213 | Q12: =Data_FAME!W19 -> 847165.67 | R12: =Data_FAME!X19 -> 847165.67 | S12: =Data_FAME!Z19 -> 0.097007586 | T12: =Data_FAME!AA19 -> 0.097007586 | U12: =Data_FAME!AD19 -> 215.27103 | V12: =Data_FAME!AE19 -> 215.27103 | W12: =Data_FAME!AH19 -> 95.797952 | Y12: =Data_FAME!AL19 -> 10.079292 | Z12: =Data_FAME!AN19 -> 10.375 | AA12: =Data_FAME!AO19 -> 10.375 | AB12: =Data_FAME!AR19 -> 0.56924052 | AC12: =Data_FAME!AT19 -> 0.61394997 | AD12: =Data_FAME!AV19 -> 73.684026 | AE12: =Data_FAME!AW19 -> 73.684026 | AF12: =Data_FAME!BB19 -> 4.3453333 | AG12: =Data_FAME!BB19 -> 4.3453333 | AH12: =Data_FAME!AS19 -> 0.56924052 | AI12: ='Data_FAME (2)'!P19 -> 38.258535 | AJ12: =Data_FAME!AI19 -> 95.797952 | AM12: ='Data_FAME (2)'!BF19 -> 244 | AN12: ='Data_FAME (2)'!BG19 -> 360 | AO12: ='Data_FAME (2)'!BH19 -> 91 | AP12: ='Data_FAME (2)'!BI19 -> 305
B13: =Data_FAME!A20 -> 33785 | C13: =Data_FAME!B20 -> 62.416759 | D13: =Data_FAME!C20 -> 60.420047 | E13: =Data_FAME!D20 -> 63.194403 | F13: =Data_FAME!F20 -> 44.452914 | G13: =Data_FAME!H20 -> 118.72539 | H13: =Data_FAME!J20 -> 59.723829 | I13: ='Data_FAME (2)'!L20 -> 52.427892 | J13: ='Data_FAME (2)'!M20 -> 51.90606 | K13: ='Data_FAME (2)'!O20 -> 38.383855 | M13: =Data_FAME!Q20 -> 372751 | N13: =Data_FAME!R20 -> 372751 | O13: =Data_FAME!T20 -> -3.1236345 | P13: =Data_FAME!U20 -> -1.8203614 | Q13: =Data_FAME!W20 -> 847646.6 | R13: =Data_FAME!X20 -> 847646.6 | S13: =Data_FAME!Z20 -> 0.09785394 | T13: =Data_FAME!AA20 -> 0.09785394 | U13: =Data_FAME!AD20 -> 216.52634 | V13: =Data_FAME!AE20 -> 216.52634 | W13: =Data_FAME!AH20 -> 97.573482 | Y13: =Data_FAME!AL20 -> 9.7404194 | Z13: =Data_FAME!AN20 -> 10.0471 | AA13: =Data_FAME!AO20 -> 10.0471 | AB13: =Data_FAME!AR20 -> 0.56506054 | AC13: =Data_FAME!AT20 -> 0.60791183 | AD13: =Data_FAME!AV20 -> 74.734655 | AE13: =Data_FAME!AW20 -> 74.734655 | AF13: =Data_FAME!BB20 -> 4.0467864 | AG13: =Data_FAME!BB20 -> 4.0467864 | AH13: =Data_FAME!AS20 -> 0.56506054 | AI13: ='Data_FAME (2)'!P20 -> 38.383855 | AJ13: =Data_FAME!AI20 -> 97.573482 | AM13: ='Data_FAME (2)'!BF20 -> 244 | AN13: ='Data_FAME (2)'!BG20 -> 360 | AO13: ='Data_FAME (2)'!BH20 -> 91 | AP13: ='Data_FAME (2)'!BI20 -> 305
B14: =Data_FAME!A21 -> 33877 | C14: =Data_FAME!B21 -> 62.691059 | D14: =Data_FAME!C21 -> 60.685211 | E14: =Data_FAME!D21 -> 63.067373 | F14: =Data_FAME!F21 -> 44.967908 | G14: =Data_FAME!H21 -> 118.80745 | H14: =Data_FAME!J21 -> 59.567454 | I14: ='Data_FAME (2)'!L21 -> 51.973211 | J14: ='Data_FAME (2)'!M21 -> 52.023965 | K14: ='Data_FAME (2)'!O21 -> 38.275282 | M14: =Data_FAME!Q21 -> 374537 | N14: =Data_FAME!R21 -> 374537 | O14: =Data_FAME!T21 -> -3.3243309 | P14: =Data_FAME!U21 -> -0.85749752 | Q14: =Data_FAME!W21 -> 840427.1 | R14: =Data_FAME!X21 -> 840427.1 | S14: =Data_FAME!Z21 -> 0.099370554 | T14: =Data_FAME!AA21 -> 0.099370554 | U14: =Data_FAME!AD21 -> 219.44681 | V14: =Data_FAME!AE21 -> 219.44681 | W14: =Data_FAME!AH21 -> 96.710815 | Y14: =Data_FAME!AL21 -> 9.695813 | Z14: =Data_FAME!AN21 -> 9.7673 | AA14: =Data_FAME!AO21 -> 9.7673 | AB14: =Data_FAME!AR21 -> 0.56539814 | AC14: =Data_FAME!AT21 -> 0.60273627 | AD14: =Data_FAME!AV21 -> 75.563565 | AE14: =Data_FAME!AW21 -> 75.563565 | AF14: =Data_FAME!BB21 -> 3.8414337 | AG14: =Data_FAME!BB21 -> 3.8414337 | AH14: =Data_FAME!AS21 -> 0.56539814 | AI14: ='Data_FAME (2)'!P21 -> 38.275282 | AJ14: =Data_FAME!AI21 -> 96.710815 | AM14: ='Data_FAME (2)'!BF21 -> 244 | AN14: ='Data_FAME (2)'!BG21 -> 360 | AO14: ='Data_FAME (2)'!BH21 -> 91 | AP14: ='Data_FAME (2)'!BI21 -> 305
B15: =Data_FAME!A22 -> 33969 | C15: =Data_FAME!B22 -> 63.195466 | D15: =Data_FAME!C22 -> 61.173856 | E15: =Data_FAME!D22 -> 63.467567 | F15: =Data_FAME!F22 -> 45.533479 | G15: =Data_FAME!H22 -> 118.62097 | H15: =Data_FAME!J22 -> 60.084592 | I15: ='Data_FAME (2)'!L22 -> 52.154689 | J15: ='Data_FAME (2)'!M22 -> 52.659248 | K15: ='Data_FAME (2)'!O22 -> 38.984401 | M15: =Data_FAME!Q22 -> 377418 | N15: =Data_FAME!R22 -> 377418 | O15: =Data_FAME!T22 -> -3.2279251 | P15: =Data_FAME!U22 -> -0.27664328 | Q15: =Data_FAME!W22 -> 832788.39 | R15: =Data_FAME!X22 -> 832788.39 | S15: =Data_FAME!Z22 -> 0.10371119 | T15: =Data_FAME!AA22 -> 0.10371119 | U15: =Data_FAME!AD22 -> 221.35146 | V15: =Data_FAME!AE22 -> 221.35146 | W15: =Data_FAME!AH22 -> 84.845339 | Y15: =Data_FAME!AL22 -> 7.1698732 | Z15: =Data_FAME!AN22 -> 7.5313 | AA15: =Data_FAME!AO22 -> 7.5313 | AB15: =Data_FAME!AR22 -> 0.59920423 | AC15: =Data_FAME!AT22 -> 0.64263116 | AD15: =Data_FAME!AV22 -> 76.644093 | AE15: =Data_FAME!AW22 -> 76.644093 | AF15: =Data_FAME!BB22 -> 3.5328715 | AG15: =Data_FAME!BB22 -> 3.5328715 | AH15: =Data_FAME!AS22 -> 0.59920423 | AI15: ='Data_FAME (2)'!P22 -> 38.984401 | AJ15: =Data_FAME!AI22 -> 84.845339 | AM15: ='Data_FAME (2)'!BF22 -> 244 | AN15: ='Data_FAME (2)'!BG22 -> 360 | AO15: ='Data_FAME (2)'!BH22 -> 91 | AP15: ='Data_FAME (2)'!BI22 -> 305
B16: =Data_FAME!A23 -> 34059 | C16: =Data_FAME!B23 -> 63.53193 | D16: =Data_FAME!C23 -> 61.499755 | E16: =Data_FAME!D23 -> 63.530914 | F16: =Data_FAME!F23 -> 46.101573 | G16: =Data_FAME!H23 -> 118.15539 | H16: =Data_FAME!J23 -> 60.484175 | I16: ='Data_FAME (2)'!L23 -> 53.053856 | J16: ='Data_FAME (2)'!M23 -> 53.005409 | K16: ='Data_FAME (2)'!O23 -> 39.383108 | M16: =Data_FAME!Q23 -> 379370 | N16: =Data_FAME!R23 -> 379370 | O16: =Data_FAME!T23 -> -3.0780999 | P16: =Data_FAME!U23 -> -0.54416477 | Q16: =Data_FAME!W23 -> 832300.53 | R16: =Data_FAME!X23 -> 832300.53 | S16: =Data_FAME!Z23 -> 0.10618491 | T16: =Data_FAME!AA23 -> 0.10618491 | U16: =Data_FAME!AD23 -> 221.58357 | V16: =Data_FAME!AE23 -> 221.58357 | W16: =Data_FAME!AH23 -> 83.282759 | Y16: =Data_FAME!AL23 -> 5.9494269 | Z16: =Data_FAME!AN23 -> 6.129 | AA16: =Data_FAME!AO23 -> 6.129 | AB16: =Data_FAME!AR23 -> 0.62407768 | AC16: =Data_FAME!AT23 -> 0.67454707 | AD16: =Data_FAME!AV23 -> 77.756408 | AE16: =Data_FAME!AW23 -> 77.756408 | AF16: =Data_FAME!BB23 -> 3.0711828 | AG16: =Data_FAME!BB23 -> 3.0711828 | AH16: =Data_FAME!AS23 -> 0.62407768 | AI16: ='Data_FAME (2)'!P23 -> 39.383108 | AJ16: =Data_FAME!AI23 -> 83.282759 | AM16: ='Data_FAME (2)'!BF23 -> 228 | AN16: ='Data_FAME (2)'!BG23 -> 343 | AO16: ='Data_FAME (2)'!BH23 -> 91 | AP16: ='Data_FAME (2)'!BI23 -> 338
... B145: =Data_FAME!A152 -> 45838 | C145: =Data_FAME!B152 -> 137.87157 | D145: =Data_FAME!C152 -> 137.87146 | E145: =Data_FAME!D152 -> 138.04057 | F145: =Data_FAME!F152 -> 142.47561 | G145: =Data_FAME!H152 -> 122.70051 | H145: =Data_FAME!J152 -> 140.78271 | I145: ='Data_FAME (2)'!L152 -> 144.80364 | J145: ='Data_FAME (2)'!M152 -> 144.36323 | K145: ='Data_FAME (2)'!O152 -> 152.26305 | M145: =Data_FAME!Q152 -> 705403 | N145: =Data_FAME!R152 -> 705403 | O145: =Data_FAME!T152 -> -0.53521004 | P145: =Data_FAME!U152 -> -1.8925383 | Q145: =Data_FAME!W152 -> 1092607.1 | R145: =Data_FAME!X152 -> 1092607.1 | S145: =Data_FAME!Z152 -> 0.04660112 | T145: =Data_FAME!AA152 -> 0.04660112 | U145: =Data_FAME!AD152 -> 670.36599 | V145: =Data_FAME!AE152 -> 670.36599 | W145: =Data_FAME!AH152 -> 85.433745 | Y145: =Data_FAME!AL152 -> 4.1790199 | Z145: =Data_FAME!AN152 -> 3.7371024 | AA145: =Data_FAME!AO152 -> 3.7425486 | AB145: =Data_FAME!AR152 -> 0.99181196 | AC145: =Data_FAME!AT152 -> 1.0097549 | AD145: =Data_FAME!AV152 -> 169.42098 | AE145: =Data_FAME!AW152 -> 169.42098 | AF145: =Data_FAME!BB152 -> 4.0110426 | AG145: =Data_FAME!BB152 -> 4.0110426 | AH145: =Data_FAME!AS152 -> 0.99106811 | AI145: ='Data_FAME (2)'!P152 -> 153.38041 | AJ145: =Data_FAME!AI152 -> 85.433745 | AM145: ='Data_FAME (2)'!BF152 -> 151.1486 | AN145: ='Data_FAME (2)'!BG152 -> 286.3633 | AO145: ='Data_FAME (2)'!BH152 -> 61.6527 | AP145: ='Data_FAME (2)'!BI152 -> 500.8354
B146: =Data_FAME!A153 -> 45930 | C146: =Data_FAME!B153 -> 139.17556 | D146: =Data_FAME!C153 -> 139.17544 | E146: =Data_FAME!D153 -> 138.97188 | F146: =Data_FAME!F153 -> 143.83211 | G146: =Data_FAME!H153 -> 123.18805 | H146: =Data_FAME!J153 -> 142.64323 | I146: ='Data_FAME (2)'!L153 -> 146.02696 | J146: ='Data_FAME (2)'!M153 -> 146.17239 | K146: ='Data_FAME (2)'!O153 -> 153.78204 | M146: =Data_FAME!Q153 -> 706813.81 | N146: =Data_FAME!R153 -> 706813.81 | P146: =Data_FAME!U153 -> -1.6978608 | Q146: =Data_FAME!W153 -> 1088109.9 | R146: =Data_FAME!X153 -> 1088109.9 | S146: =Data_FAME!Z153 -> 0.048668948 | T146: =Data_FAME!AA153 -> 0.048668948 | U146: =Data_FAME!AD153 -> 674.78348 | V146: =Data_FAME!AE153 -> 675.06649 | W146: =Data_FAME!AH153 -> 84.985242 | Y146: =Data_FAME!AL153 -> 3.9805726 | Z146: =Data_FAME!AN153 -> 3.623433 | AA146: =Data_FAME!AO153 -> 3.623433 | AB146: =Data_FAME!AR153 -> 0.98826679 | AC146: =Data_FAME!AT153 -> 1.006946 | AD146: =Data_FAME!AV153 -> 170.10292 | AE146: =Data_FAME!AW153 -> 170.10291 | AF146: =Data_FAME!BB153 -> 3.9691108 | AG146: ='Data_FAME (2)'!BD153 -> 3.9691108 | AH146: =Data_FAME!AS153 -> 0.98826679 | AI146: ='Data_FAME (2)'!P153 -> 152.77858 | AJ146: =Data_FAME!AI153 -> 84.985242 | AM146: ='Data_FAME (2)'!BF153 -> 151.1486 | AN146: ='Data_FAME (2)'!BG153 -> 286.3633 | AO146: ='Data_FAME (2)'!BH153 -> 61.6527 | AP146: ='Data_FAME (2)'!BI153 -> 500.8354
B147: =Data_FAME!A154 -> 46022 | C147: =Data_FAME!B154 -> 139.91004 | D147: =Data_FAME!C154 -> 139.90992 | E147: =Data_FAME!D154 -> 139.85387 | F147: =Data_FAME!F154 -> 144.83827 | G147: =Data_FAME!H154 -> 123.51261 | H147: =Data_FAME!J154 -> 144.14372 | I147: ='Data_FAME (2)'!L154 -> 146.88064 | J147: ='Data_FAME (2)'!M154 -> 147.33385 | K147: ='Data_FAME (2)'!O154 -> 153.89556 | M147: =Data_FAME!Q154 -> 708934.25 | N147: =Data_FAME!R154 -> 708934.25 | P147: =Data_FAME!U154 -> -1.8289475 | Q147: =Data_FAME!W154 -> 1089925.4 | R147: =Data_FAME!X154 -> 1089925.4 | S147: =Data_FAME!Z154 -> 0.049697693 | T147: =Data_FAME!AA154 -> 0.049697693 | V147: =Data_FAME!AE154 -> 680.79359 | Z147: =Data_FAME!AN154 -> 3.5100422 | AA147: =Data_FAME!AO154 -> 3.5100422 | AB147: =Data_FAME!AR154 -> 0.98263827 | AD147: =Data_FAME!AV154 -> 170.38249 | AE147: =Data_FAME!AW154 -> 170.38248 | AG147: ='[2]VAR expectations'!C155 -> 3.9221779 | AH147: =Data_FAME!AS154 -> 0.98263827 | AI147: ='Data_FAME (2)'!P154 -> 154.08739 | AJ147: =Data_FAME!AI154 -> 84.479013 | AM147: ='Data_FAME (2)'!BF154 -> 151.1486 | AN147: ='Data_FAME (2)'!BG154 -> 286.3633 | AO147: ='Data_FAME (2)'!BH154 -> 61.6527 | AP147: ='Data_FAME (2)'!BI154 -> 500.8354
B148: =Data_FAME!A155 -> 46112 | E148: =Data_FAME!D155 -> 139.85387 | I148: ='Data_FAME (2)'!L155 -> 148.75767 | J148: ='Data_FAME (2)'!M155 -> 0 | K148: ='Data_FAME (2)'!O155 -> 0 | N148: =Data_FAME!R155 -> 711292.91 | P148: =Data_FAME!U155 -> -1.7040186 | R148: =Data_FAME!X155 -> 1088841.3 | T148: =Data_FAME!AA155 -> 0.0504 | V148: =Data_FAME!AE155 -> 686.71173 | Z148: =Data_FAME!AN155 -> 3.4154219 | AA148: =Data_FAME!AO155 -> 3.4154219 | AD148: =Data_FAME!AV155 -> 170.76719 | AE148: =Data_FAME!AW155 -> 170.76718 | AG148: ='[2]VAR expectations'!C156 -> 3.4732572 | AH148: =Data_FAME!AS155 -> 0.97725801 | AI148: ='Data_FAME (2)'!P155 -> 152.38088 | AJ148: =Data_FAME!AI155 -> 84.252156 | AM148: ='Data_FAME (2)'!BF155 -> 146.37555 | AN148: ='Data_FAME (2)'!BG155 -> 277.06973 | AO148: ='Data_FAME (2)'!BH155 -> 58.33398 | AP148: ='Data_FAME (2)'!BI155 -> 518.22073
B149: =Data_FAME!A156 -> 46203 | E149: =Data_FAME!D156 -> 139.85387 | I149: ='Data_FAME (2)'!L156 -> 149.8334 | J149: ='Data_FAME (2)'!M156 -> 0 | K149: ='Data_FAME (2)'!O156 -> 0 | N149: =Data_FAME!R156 -> 713598.35 | P149: =Data_FAME!U156 -> -1.7237463 | R149: =Data_FAME!X156 -> 1089619.5 | T149: =Data_FAME!AA156 -> 0.050541252 | V149: =Data_FAME!AE156 -> 692.12433 | Z149: =Data_FAME!AN156 -> 3.3219454 | AA149: =Data_FAME!AO156 -> 3.3219454 | AD149: =Data_FAME!AV156 -> 171.28775 | AE149: =Data_FAME!AW156 -> 171.28774 | AG149: ='[2]VAR expectations'!C157 -> 3.2071262 | AH149: =Data_FAME!AS156 -> 0.9749504 | AI149: ='Data_FAME (2)'!P156 -> 148.04947 | AJ149: =Data_FAME!AI156 -> 84.117539 | AM149: ='Data_FAME (2)'!BF156 -> 146.73083 | AN149: ='Data_FAME (2)'!BG156 -> 276.4363 | AO149: ='Data_FAME (2)'!BH156 -> 58.33497 | AP149: ='Data_FAME (2)'!BI156 -> 518.4979
B150: =Data_FAME!A157 -> 46295 | E150: =Data_FAME!D157 -> 139.85387 | I150: ='Data_FAME (2)'!L157 -> 149.92516 | J150: ='Data_FAME (2)'!M157 -> 0 | K150: ='Data_FAME (2)'!O157 -> 0 | N150: =Data_FAME!R157 -> 716034.92 | P150: =Data_FAME!U157 -> -1.6558511 | R150: =Data_FAME!X157 -> 1090427.8 | T150: =Data_FAME!AA157 -> 0.050498257 | V150: =Data_FAME!AE157 -> 697.3824 | Z150: =Data_FAME!AN157 -> 3.3064318 | AA150: =Data_FAME!AO157 -> 3.3064318 | AD150: =Data_FAME!AV157 -> 172.08142 | AE150: =Data_FAME!AW157 -> 172.08141 | AG150: ='[2]VAR expectations'!C158 -> 2.9284517 | AH150: =Data_FAME!AS157 -> 0.97388427 | AI150: ='Data_FAME (2)'!P157 -> 149.5711 | AJ150: =Data_FAME!AI157 -> 83.98531 | AM150: ='Data_FAME (2)'!BF157 -> 146.73083 | AN150: ='Data_FAME (2)'!BG157 -> 276.4363 | AO150: ='Data_FAME (2)'!BH157 -> 58.33497 | AP150: ='Data_FAME (2)'!BI157 -> 518.4979
B151: =Data_FAME!A158 -> 46387 | E151: =Data_FAME!D158 -> 139.85387 | I151: ='Data_FAME (2)'!L158 -> 151.64689 | J151: ='Data_FAME (2)'!M158 -> 0 | K151: ='Data_FAME (2)'!O158 -> 0 | N151: =Data_FAME!R158 -> 718746.04 | P151: =Data_FAME!U158 -> -1.6089581 | R151: =Data_FAME!X158 -> 1092228.2 | T151: =Data_FAME!AA158 -> 0.050389561 | V151: =Data_FAME!AE158 -> 702.54561 | Z151: =Data_FAME!AN158 -> 3.3371672 | AA151: =Data_FAME!AO158 -> 3.3371672 | AD151: =Data_FAME!AV158 -> 172.82848 | AE151: =Data_FAME!AW158 -> 172.82847 | AG151: ='[2]VAR expectations'!C159 -> 2.7607717 | AH151: =Data_FAME!AS158 -> 0.97306004 | AI151: ='Data_FAME (2)'!P158 -> 149.37929 | AJ151: =Data_FAME!AI158 -> 83.853892 | AM151: ='Data_FAME (2)'!BF158 -> 146.73083 | AN151: ='Data_FAME (2)'!BG158 -> 276.4363 | AO151: ='Data_FAME (2)'!BH158 -> 58.33497 | AP151: ='Data_FAME (2)'!BI158 -> 518.4979
B152: =Data_FAME!A159 -> 46477 | E152: =Data_FAME!D159 -> 139.85387 | I152: ='Data_FAME (2)'!L159 -> 0 | J152: ='Data_FAME (2)'!M159 -> 0 | K152: ='Data_FAME (2)'!O159 -> 0 | N152: =Data_FAME!R159 -> 721631.31 | P152: =Data_FAME!U159 -> -1.5371047 | R152: =Data_FAME!X159 -> 1094167.4 | T152: =Data_FAME!AA159 -> 0.05021789 | V152: =Data_FAME!AE159 -> 707.66289 | Z152: =Data_FAME!AN159 -> 3.376846 | AA152: =Data_FAME!AO159 -> 3.376846 | AD152: =Data_FAME!AV159 -> 173.77928 | AE152: =Data_FAME!AW159 -> 173.77927 | AG152: ='[2]VAR expectations'!C160 -> 2.6830774 | AH152: =Data_FAME!AS159 -> 0.97240044 | AI152: ='Data_FAME (2)'!P159 -> 148.75311 | AJ152: =Data_FAME!AI159 -> 83.722428 | AM152: ='Data_FAME (2)'!BF159 -> 146.37555 | AN152: ='Data_FAME (2)'!BG159 -> 277.06973 | AO152: ='Data_FAME (2)'!BH159 -> 58.33398 | AP152: ='Data_FAME (2)'!BI159 -> 518.22073
B153: =Data_FAME!A160 -> 46568 | E153: =Data_FAME!D160 -> 139.85387 | I153: ='Data_FAME (2)'!L160 -> 0 | J153: ='Data_FAME (2)'!M160 -> 0 | K153: ='Data_FAME (2)'!O160 -> 0 | N153: =Data_FAME!R160 -> 724747.91 | P153: =Data_FAME!U160 -> -1.4586119 | R153: =Data_FAME!X160 -> 1096113.2 | T153: =Data_FAME!AA160 -> 0.05003043 | V153: =Data_FAME!AE160 -> 712.79819 | Z153: =Data_FAME!AN160 -> 3.4138167 | AA153: =Data_FAME!AO160 -> 3.4138167 | AD153: =Data_FAME!AV160 -> 174.72296 | AE153: =Data_FAME!AW160 -> 174.72296 | AG153: ='[2]VAR expectations'!C161 -> 2.6433548 | AH153: =Data_FAME!AS160 -> 0.97421349 | AI153: ='Data_FAME (2)'!P160 -> 149.36955 | AJ153: =Data_FAME!AI160 -> 83.591451 | AM153: ='Data_FAME (2)'!BF160 -> 146.73083 | AN153: ='Data_FAME (2)'!BG160 -> 276.4363 | AO153: ='Data_FAME (2)'!BH160 -> 58.33497 | AP153: ='Data_FAME (2)'!BI160 -> 518.4979
